Workbook

Sheet Input data
A1: Cross | B1: Replicate | C1: Egg number | E1: Larvae number | G1: Percentage hatch rate | J1: Engorged female num | M1: Number that laid | O1: Percent
A2: WTxSDA-500 | B2: 1 | C2: 121 | E2: 111 | G2: =E2/C2*100 -> 91.735537 | J2: 8 | M2: 6 | O2: =M2/J2*100 -> 75 | V2: Dead
A3: WTxSDA-500 | B3: 1 | C3: 134 | E3: 116 | G3: =E3/C3*100 -> 86.567164 | V3: Half dead
A4: WTxSDA-500 | B4: 1 | C4: 83 | E4: 0 | G4: =E4/C4*100 -> 0
A5: WTxSDA-500 | B5: 1 | C5: 118 | E5: 92 | G5: =E5/C5*100 -> 77.966102
A6: WTxSDA-500 | B6: 1 | C6: 81 | E6: 66 | G6: =E6/C6*100 -> 81.481481
A7: WTxSDA-500 | B7: 1 | C7: 0 | E7: 0 | G7: 0
A8: WTxSDA-500 | B8: 1 | C8: 102 | E8: 88 | G8: =E8/C8*100 -> 86.27451
A9: WTxSDA-500 | B9: 1 | C9: 0
A10: WTxSDA-500 | B10: 2 | C10: 0 | J10: 8 | M10: 6 | O10: =M10/J10*100 -> 75
A11: WTxSDA-500 | B11: 2 | C11: 0
A12: WTxSDA-500 | B12: 2 | C12: 217 | E12: 200 | G12: =E12/C12*100 -> 92.165899
A13: WTxSDA-500 | B13: 2 | C13: 147 | E13: 106 | G13: =E13/C13*100 -> 72.108844
A14: WTxSDA-500 | B14: 2 | C14: 153 | E14: 128 | G14: =E14/C14*100 -> 83.660131
A15: WTxSDA-500 | B15: 2 | C15: 146 | E15: 123 | G15: =E15/C15*100 -> 84.246575
A16: WTxSDA-500 | B16: 2 | C16: 88 | E16: 147 | G16: =E16/C16*100 -> 167.04545
A17: WTxSDA-500 | B17: 2 | C17: 169 | E17: 148 | G17: =E17/C17*100 -> 87.573964
A18: WTxSDA-500 | B18: 3 | C18: 75 | E18: 0 | G18: =E18/C18*100 -> 0 | J18: 8 | M18: 7 | O18: =M18/J18*100 -> 87.5
A19: WTxSDA-500 | B19: 3 | C19: 84 | E19: 14 | G19: =E19/C19*100 -> 16.666667
A20: WTxSDA-500 | B20: 3 | C20: 160 | E20: 135 | G20: =E20/C20*100 -> 84.375
A21: WTxSDA-500 | B21: 3 | C21: 126 | E21: 107 | G21: =E21/C21*100 -> 84.920635
A22: WTxSDA-500 | B22: 3 | C22: 0
A23: WTxSDA-500 | B23: 3 | C23: 123 | E23: 111 | G23: =E23/C23*100 -> 90.243902
A24: WTxSDA-500 | B24: 3 | C24: 68 | E24: 0 | G24: =E24/C24*100 -> 0
A25: WTxSDA-500 | B25: 3 | C25: 199 | E25: 160 | G25: =E25/C25*100 -> 80.40201
A26: WTxSDA-500 | B26: 4 | C26: 144 | E26: 131 | G26: =E26/C26*100 -> 90.972222 | J26: 8 | M26: 7 | O26: =M26/J26*100 -> 87.5
A27: WTxSDA-500 | B27: 4 | C27: 151 | E27: 55 | G27: =E27/C27*100 -> 36.423841
A28: WTxSDA-500 | B28: 4 | C28: 0
A29: WTxSDA-500 | B29: 4 | C29: 145 | E29: 130 | G29: =E29/C29*100 -> 89.655172
A30: WTxSDA-500 | B30: 4 | C30: 112 | E30: 97 | G30: =E30/C30*100 -> 86.607143
A31: WTxSDA-500 | B31: 4 | C31: 124 | E31: 111 | G31: =E31/C31*100 -> 89.516129
A32: WTxSDA-500 | B32: 4 | C32: 172 | E32: 0 | G32: =E32/C32*100 -> 0
A33: WTxSDA-500 | B33: 4 | C33: 79 | E33: 72 | G33: =E33/C33*100 -> 91.139241
A34: WTxSDA-500 | B34: 5 | C34: 0 | J34: 9 | M34: 7 | O34: =M34/J34*100 -> 77.777778
A35: WTxSDA-500 | B35: 5 | C35: 145 | E35: 62 | G35: =E35/C35*100 -> 42.758621
A36: WTxSDA-500 | B36: 5 | C36: 153 | E36: 122 | G36: =E36/C36*100 -> 79.738562
A37: WTxSDA-500 | B37: 5 | C37: 0
A38: WTxSDA-500 | B38: 5 | C38: 138 | E38: 133 | G38: =E38/C38*100 -> 96.376812
A39: WTxSDA-500 | B39: 5 | C39: 208 | E39: 174 | G39: =E39/C39*100 -> 83.653846
A40: WTxSDA-500 | B40: 5 | C40: 181 | E40: 147 | G40: =E40/C40*100 -> 81.21547
...

Sheet Data summary
D1: Avg Eggs | E1: Avg Larvae | F1: Hatching rate | G1: Fertility fitness cost
C2: WTxSDA500 | D2: =AVERAGE('Input data'!C2:C42) -> 106.63415 | E2: =AVERAGE('Input data'!E2:E42) -> 93.764706 | F2: =E2/D2*100 -> 87.93122
C3: HetsxSDA500 | D3: =AVERAGE('Input data'!C82:C116) -> 67.685714 | E3: =AVERAGE('Input data'!E82:E116) -> 56.548387 | F3: =E3/D3*100 -> 83.545528 | G3: =D3/D2 -> 0.63474709 | H3: =E3/E2 -> 0.60308819 | I3: =F3/F2 -> 0.9501236
C4: HomsxSDA500 | D4: =AVERAGE('Input data'!C160:C203) -> 20.863636 | E4: =AVERAGE('Input data'!E160:E203) -> 23.115385 | F4: =E4/D4*100 -> 110.79269 | G4: =D4/D2 -> 0.19565624 | H4: =E4/E2 -> 0.24652543 | I4: =F4/F2 -> 1.2599927
C5: SDA500xWT | D5: =AVERAGE('Input data'!C43:C81) -> 93.435897 | E5: =AVERAGE('Input data'!E43:E81) -> 86.354839 | F5: =E5/D5*100 -> 92.421479
C6: SDA500xHets | D6: =AVERAGE('Input data'!C117:C159) -> 45.488372 | E6: =AVERAGE('Input data'!E117:E159) -> 15.342857 | F6: =E6/D6*100 -> 33.729185 | G6: =D6/D5 -> 0.48684043 | H6: =E6/E5 -> 0.17767223 | I6: =F6/F5 -> 0.36494963
C7: SDA500xHoms | D7: 0
